# Java 中基本的 try-catch-finally 异常处理

> 原文：<https://jenkov.com/tutorials/java-exception-handling/basic-try-catch-finally.html>

本文总结了 try-catch-finally 子句错误处理的基本原理。这些例子是用 Java 编写的，但是规则对于 C#是一样的。Java 和 C#异常的唯一区别是 C#没有检查异常。检查和未检查的异常在不同的文本中有更详细的解释。

异常在程序中用来表示发生了一些错误或异常情况，并且在异常被处理之前继续程序流是没有意义的。一个方法可能会因为很多原因抛出异常，例如，如果输入参数无效(应为正数时为负数，等等。).

## 调用堆栈解释道

这篇文章在几个地方提到了“调用栈”的概念。调用栈意味着从当前方法到程序的主方法的方法调用序列。如果方法 A 调用 B，B 调用 C，那么调用堆栈如下所示:

```
    A
    B
    C

```

当方法 C 返回时，调用堆栈仅包含 A 和 B。如果 B 随后调用方法 D，则调用堆栈如下所示:

```
    A
    B
    D

```

在学习异常传播的概念时，理解调用堆栈很重要。异常从最初引发它的方法沿调用堆栈向上传播，直到调用堆栈中的方法捕捉到它。稍后会详细介绍。

## 抛出异常

如果一个方法需要能够抛出异常，它必须在方法签名中声明抛出的异常，然后在方法中包含 throw 语句。这里有一个例子:

```
    public int divide(int numberToDivide, int numberToDivideBy)
    throws BadNumberException{
        if(numberToDivideBy == 0){
            throw new BadNumberException("Cannot divide by 0");
        }
        return numberToDivide / numberToDivideBy;
    }

```

当抛出异常时，该方法在“throw”语句后立即停止执行。“throw”语句之后的任何语句都不会被执行。在上面的例子中,“return numberToDivide/numberToDivideBy；如果引发 BadNumberException，则不执行语句。当异常在某处被“catch”块捕获时，程序恢复执行。捕捉异常将在后面解释。

您可以从代码中抛出任何类型的异常，只要您的方法签名声明了它。你也可以编造自己的例外。异常是扩展 java.lang.Exception 或任何其他内置异常类的常规 Java 类。如果一个方法声明抛出异常 A，那么抛出 A 的子类也是合法的。

## 捕捉异常

如果一个方法调用另一个引发检查异常的方法，则调用方法会被强制传递异常或捕获异常。捕捉异常是使用 try-catch 块完成的。这里有一个例子:

```
    public void callDivide(){
        try {
            int result = divide(2,1);
            System.out.println(result);
        } catch (BadNumberException e) {
            //do something clever with the exception
            System.out.println(e.getMessage());
        }
        System.out.println("Division attempt done");
    }

```

如果抛出异常，catch-clause 中的 BadNumberException 参数 e 指向从 divide 方法抛出的异常。

如果在 try-block 中调用的任何方法或执行的任何语句都没有抛出异常，那么 catch-block 就会被忽略。它不会被执行。

如果在 try-block 内部抛出异常，比如来自 Divide 方法的异常，调用方法 callDivide 的程序流就会像 divide 内部的程序流一样被中断。程序流在调用堆栈中的 catch-block 处恢复，该 catch-block 可以捕获引发的异常。在上面的示例中，“system . out . println(result)；”如果从引发异常到 divide 方法，语句将不会执行。相反，程序将在“catch (BadNumberException e) { }”块中继续执行。

如果 catch-block 内部抛出了一个异常，而这个异常没有被捕获，catch-block 就会像 try-block 一样被中断。

当 catch 块完成时，程序继续执行 catch 块后面的任何语句。在上面的示例中，“system . out . println(" Division attempt done ")；”语句总是会被执行。

## 传播异常

您不必捕获从其他方法抛出的异常。如果在调用抛出异常的方法时对异常无能为力，可以让该方法将异常沿调用堆栈向上传播到调用该方法的方法。如果这样做，调用引发异常的方法的方法也必须声明引发异常。下面是 callDivide()方法在这种情况下的样子。

```
    public void callDivide() throws BadNumberException{
        int result = divide(2,1);
        System.out.println(result);
    }

```

请注意 try-catch 块是如何消失的，callDivide 方法现在声明它可以抛出 BadNumberException。如果 divide 方法抛出异常，程序执行仍然会中断。因此“system . out . println(result)；”如果 divide 方法引发异常，则不会执行。但是现在程序执行没有在 callDivide 方法中恢复。异常被传播到调用 callDivide 的方法。直到调用堆栈中的 catch-block 捕获到异常，程序才继续执行。在引发异常的方法和捕获异常的方法之间的调用堆栈中的所有方法都在代码中引发或传播异常的位置停止执行。

## 示例:捕获 IOException 的

如果在 try-catch 块中的一系列语句中抛出异常，那么该系列语句将被中断，控制流将直接跳到 catch 块。这段代码可以在几个地方被异常中断:

```
    public void openFile(){
        try {
            // constructor may throw FileNotFoundException
            FileReader reader = new FileReader("someFile");
            int i=0;
            while(i != -1){
                //reader.read() may throw IOException
                i = reader.read();
                System.out.println((char) i );
            }
            reader.close();
            System.out.println("--- File End ---");
        } catch (FileNotFoundException e) {
            //do something clever with the exception
        } catch (IOException e) {
            //do something clever with the exception
        }
    }

```

如果 reader.read()方法调用抛出 IOException，下面的 system . out . println((char)I)；未执行。最后一个 reader.close()或 System.out.println(" - File End -")也不是；声明。相反，程序直接跳到 catch(IOException e){...} catch 子句。如果新的 FileReader(" some file ")；构造函数调用引发异常，try 块中的任何代码都不会被执行。

## 示例:传播 IOException

这段代码是前面方法的一个版本，它抛出异常而不是捕获它们:

```
    public void openFile() throws IOException {
        FileReader reader = new FileReader("someFile");
        int i=0;
        while(i != -1){
            i = reader.read();
            System.out.println((char) i );
        }
        reader.close();
        System.out.println("--- File End ---");
    }

```

如果从 reader.read()方法中抛出异常，那么程序执行将暂停，异常将通过调用堆栈传递给调用 openFile()的方法。如果调用方法有一个 try-catch 块，异常将在那里被捕获。如果调用方法也只是抛出方法，调用方法也会在 openFile()方法调用时被中断，并且异常会向上传递到调用堆栈。异常像这样沿着调用栈向上传播，直到某个方法捕获到异常，或者 Java 虚拟机捕获到异常。

## 最后

您可以将 finally-clause 附加到 try-catch 块。finally 子句中的代码将始终被执行，即使从 try 或 catch 块中引发了异常。如果您的代码在 try 或 catch 块中有一个 return 语句，那么 finally 块中的代码将在从该方法返回之前执行。以下是 finally 子句的外观:

```

    public void openFile(){
        FileReader reader = null;
        try {
            reader = new FileReader("someFile");
            int i=0;
            while(i != -1){
                i = reader.read();
                System.out.println((char) i );
            }
        } catch (IOException e) {
            //do something clever with the exception
        } finally {
            if(reader != null){
                try {
                    reader.close();
                } catch (IOException e) {
                    //do something clever with the exception
                }
            }
            System.out.println("--- File End ---");
        }
    }

```

无论在 try 或 catch 块中是否抛出异常，finally 块中的代码都会被执行。上面的例子显示了不管 try 或 catch 块中的程序流如何，文件读取器总是关闭的。

注意:如果一个异常在 finally 块中被抛出，并且没有被捕获，那么这个 finally 块就像 try-block 和 catch-block 一样被中断。这就是为什么上一个示例在包装在 try-catch 块中的 finally 块中调用 reader.close()方法:

```
    } finally {
            if(reader != null){
                try {
                    reader.close();
                } catch (IOException e) {
                    //do something clever with the exception
                }
            }
            System.out.println("--- File End ---");
        }

```

这样 system . out . println("-File End-")；方法调用将总是被执行。如果没有抛出未检查的异常，即。在后面的章节中会有更多关于选中和未选中的内容。

您不需要同时使用 catch 和 finally 块。您可以使用 try-block 拥有其中一个或两个，但不能一个都没有。这段代码不捕捉异常，而是让它在调用堆栈中向上传播。由于 finally 块，即使抛出异常，代码仍会关闭文件管理器读取器。

```
    public void openFile() throws IOException {
        FileReader reader = null;
        try {
            reader = new FileReader("someFile");
            int i=0;
            while(i != -1){
                i = reader.read();
                System.out.println((char) i );
            }
        } finally {
            if(reader != null){
                try {
                    reader.close();
                } catch (IOException e) {
                    //do something clever with the exception
                }
            }
            System.out.println("--- File End ---");
        }
    }

```

请注意 catch 块是如何消失的。

## 捕捉或传播异常？

您可能想知道是否应该捕获或处理程序中抛出的异常。看情况吧。在许多应用程序中，你不能对异常做太多，只能告诉用户请求的操作失败了。在这些应用程序中，您通常可以在调用堆栈中的第一个方法中集中捕获所有或大多数异常。您可能仍然需要在传播异常时处理它(使用 finally 子句)。例如，如果 web 应用程序中的数据库连接出现错误，您可能仍然必须在 finally 子句中关闭数据库连接，即使您除了告诉用户操作失败之外什么也做不了。如何处理异常还取决于您为应用程序选择的是检查异常还是未检查异常。在错误处理线索的其他文本中有更多关于这方面的内容。