# Java 中的异常丰富

> 原文：<https://jenkov.com/tutorials/java-exception-handling/exception-enrichment.html>

异常丰富是[异常包装](exception-wrapping.html)的替代方案。异常包装有几个缺点，异常丰富可以解决。这些缺点是:

*   异常包装可能会导致很长的堆栈跟踪，包装层次结构中的每个异常都有一个堆栈跟踪。通常只有根栈跟踪是有意义的。剩下的堆栈跟踪就很烦人了。

*   异常消息分散在堆栈跟踪中。异常消息通常打印在堆栈跟踪的上方。当几个异常在层次结构中相互包装时，所有这些消息都分散在堆栈跟踪之间。这使得确定哪里出错，以及当错误发生时程序试图做什么变得更加困难。换句话说，这使得很难确定错误是在什么上下文中发生的。错误可能发生在 PersonDao 类中，但是当它失败时，是从 servlet 还是从 web 服务调用它呢？

在异常丰富中，不包装异常。相反，您可以向原始异常添加上下文信息并重新抛出它。重新引发异常不会重置嵌入异常中的堆栈跟踪。

这里有一个例子:

```
  public void method2() throws EnrichableException{
     try{
        method1(); 
     } catch(EnrichableException e){
        e.addInfo("An error occurred when trying to ...");
        throw e;
     }
  }

  public void method1() throws EnrichableException {
     if(...) throw new EnrichableException(
        "Original error message");   
  }

```

正如你所看到的，method1()抛出了 EnrichableException，它是 enrichable exception 的超类。这不是标准的 Java 异常，所以您必须自己创建它。本文末尾有一个 EnrichableException 示例。

注意 method2()如何在捕获的 EnrichableException 上调用 addInfo()方法，并在之后重新抛出它。随着异常在调用堆栈中向上传播，每个 catch 块都可以在必要时向异常添加相关信息。

使用这种简单的技术，您只能获得一个堆栈跟踪，但仍然可以获得调查异常原因所需的任何相关上下文信息。

## 唯一错误代码

有时需要用唯一的错误代码来标识应用程序中出现的每个错误。这可能有点问题，因为在整个应用程序中重用的组件内部会出现一些错误。因此，对于抛出异常的组件来说，异常可能看起来是相同的，但是异常发生的上下文是不同的。

这里有一个例子:

```
  public void method3() throws EnrichableException{
     try{
        method1(); 
     } catch(EnrichableException e){
        e.addInfo("An error occurred when trying to ...");
        throw e;
     }
  }

  public void method2() throws EnrichableException{
     try{
        method1(); 
     } catch(EnrichableException e){
        e.addInfo("An error occurred when trying to ...");
        throw e;
     }
  }

  public void method1() throws EnrichableException {
     if(...) throw new EnrichableException(
        "ERROR1", "Original error message");   
  }

```

请注意 method1()如何将代码“ERROR1”添加到抛出的 EnrichableException 中，以唯一地标识错误原因。但是还要注意，method1()是从 method2()和 method3()中调用的。尽管无论调用它的是 method2()还是 method3()，错误对 method1()来说似乎都是一样的，但对于调查错误的开发人员来说，知道这一点可能很重要。错误代码“ERROR1”足以确定错误发生在哪里，但不能确定错误发生在什么上下文中。

这个问题的解决方案是以添加其他上下文信息的相同方式向异常添加唯一的上下文错误代码。下面是一个示例，其中 addInfo()方法已被更改以适应这种情况:

```
  public void method3() throws EnrichableException{
     try{
        method1(); 
     } catch(EnrichableException e){
        e.addInfo("METHOD3", "ERROR1",
            "An error occurred when trying to ...");
        throw e;
     }
  }

  public void method2() throws EnrichableException{
     try{
        method1(); 
     } catch(EnrichableException e){
        e.addInfo("METHOD2", "ERROR1",
            "An error occurred when trying to ...");
        throw e;
     }
  }

  public void method1() throws EnrichableException {
     if(...) throw new EnrichableException(
        "METHOD1", "ERROR1", "Original error message");   
  }

```

addInfo()方法和 EnrichableException 的构造函数中添加了两个新参数。第一个参数是标识发生错误的上下文的代码。第二个参数是上下文中唯一的错误代码。当从 method2()调用时，method1()引发的异常的错误标识将如下所示:

```
 [METHOD2:ERROR1][METHOD1:ERROR1]

```

当从方法 3()调用方法 1()时，错误标识将如下所示:

```
 [METHOD3:ERROR1][METHOD1:ERROR1]

```

如您所见，现在可以区分从 method1()通过 method2()抛出的异常和从 method1()通过 method3()抛出的异常。

您可能并不总是需要额外的上下文错误代码，但是当您需要时，本节中概述的解决方案是一个选项。

## 包装不可浓缩的例外

您可能无法总是避免异常包装。如果应用程序中的某个组件引发了一个不可浓缩的检查异常，您可能需要将它包装在一个可浓缩的异常中。下面是一个示例，其中 method1()捕获一个不可浓缩的异常，并将其包装在一个可浓缩的异常中，然后引发可浓缩的异常:

```
  public void method1() throws EnrichableException {

     try{

        ... call some method that throws an IOException ...

     } catch(IOException ioexception)
        throw new EnrichableException( ioexception,
          "METHOD1", "ERROR1", "Original error message");   
  }

```

## 未检查的 EnrichableException

我过去一直支持检查异常，但是在过去的几年里，我的观点发生了变化。现在我觉得检查异常与其说是帮助，不如说是麻烦。因此，我更愿意通过扩展 RuntimeException 来不检查我的 EnrichableException。

在文本[“已检查与未检查异常”](checked-or-unchecked-exceptions.html)中对已检查和未检查异常进行了更全面的讨论。

## 异常丰富和可插入的异常处理程序

与任何其他异常类型一样，可以将可插入异常处理程序与可丰富异常一起使用。如果您使用前面描述的唯一错误代码，这些代码必须作为参数添加到异常处理程序接口中。以下是支持这些唯一错误代码的异常处理程序接口示例:

```
public interface ExceptionHandler{

   public void handle(String contextCode, String errorCode,
                      String errorText, Throwable t)

   public void raise(String contextCode, String errorCode,
                     String errorText);

}

```

程序中捕获的异常将被传递给 handleException()，后者将决定抛出什么具体的异常。在这种情况下，会引发 EnrichableException。如果 EnrichableException 未选中，则没有必要在 handleException()方法中声明它。

## 一个例子 EnrichableException

下面是一个可合并例外的实例，您可以将其用作自己的可合并例外的模板。您可能需要更改类定义以适应自己的需要。如本文前面所述，该异常旨在使用唯一的错误代码。

代码下面是一个使用 EnrichableException 的示例应用程序，以及由此应用程序生成的堆栈跟踪。

```
import java.util.ArrayList;
import java.util.List;

public class EnrichableException extends RuntimeException {
    public static final long serialVersionUID = -1;

    protected List<InfoItem> infoItems =
            new ArrayList<InfoItem>();

    protected class InfoItem{
        public String errorContext = null;
        public String errorCode  = null;
        public String errorText  = null;
        public InfoItem(String contextCode, String errorCode,
                                     String errorText){

            this.errorContext = contextCode;
            this.errorCode   = errorCode;
            this.errorText   = errorText;
        }
    }

    public EnrichableException(String errorContext, String errorCode,
                               String errorMessage){

        addInfo(errorContext, errorCode, errorMessage);
    }

    public EnrichableException(String errorContext, String errorCode,
                               String errorMessage, Throwable cause){
        super(cause);
        addInfo(errorContext, errorCode, errorMessage);
    }

    public EnrichableException addInfo(
        String errorContext, String errorCode, String errorText){

        this.infoItems.add(
            new InfoItem(errorContext, errorCode, errorText));
        return this;
    }

    public String getCode(){
        StringBuilder builder = new StringBuilder();

        for(int i = this.infoItems.size()-1 ; i >=0; i--){
            InfoItem info =
                this.infoItems.get(i);
            builder.append('[');
            builder.append(info.errorContext);
            builder.append(':');
            builder.append(info.errorCode);
            builder.append(']');
        }

        return builder.toString();
    }

    public String toString(){
        StringBuilder builder = new StringBuilder();

        builder.append(getCode());
        builder.append('\n');

        //append additional context information.
        for(int i = this.infoItems.size()-1 ; i >=0; i--){
            InfoItem info =
                this.infoItems.get(i);
            builder.append('[');
            builder.append(info.errorContext);
            builder.append(':');
            builder.append(info.errorCode);
            builder.append(']');
            builder.append(info.errorText);
            if(i>0) builder.append('\n');
        }

        //append root causes and text from this exception first.
        if(getMessage() != null) {
            builder.append('\n');
            if(getCause() == null){
                builder.append(getMessage());
            } else if(!getMessage().equals(getCause().toString())){
                builder.append(getMessage());
            }
        }
        appendException(builder, getCause());

        return builder.toString();
    }

    private void appendException(
            StringBuilder builder, Throwable throwable){
        if(throwable == null) return;
        appendException(builder, throwable.getCause());
        builder.append(throwable.toString());
        builder.append('\n');
    }

```

```
[L1:E1][L2:E2][L3:E3]
[L1:E1]Error in level 1, calling level 2
[L2:E2]Error in level 2, calling level 3
[L3:E3]Error at level 3
java.lang.IllegalArgumentException: incorrect argument passed

	at exception.ExceptionTest$1.handle(ExceptionTest.java:8)
	at exception.ExceptionTest.level3(ExceptionTest.java:49)
	at exception.ExceptionTest.level2(ExceptionTest.java:38)
	at exception.ExceptionTest.level1(ExceptionTest.java:29)
	at exception.ExceptionTest.main(ExceptionTest.java:21)
Caused by: java.lang.IllegalArgumentException: incorrect argument passed
	at exception.ExceptionTest.level4(ExceptionTest.java:54)
	at exception.ExceptionTest.level3(ExceptionTest.java:47)
	... 3 more

```

```
public class ExceptionTest {

    protected ExceptionHandler exceptionHandler = new ExceptionHandler(){
        public void handle(String errorContext, String errorCode,
                           String errorText, Throwable t){

            if(! (t instanceof EnrichableException)){
                throw new EnrichableException(
                    errorContext, errorCode, errorText, t);
            } else {
                ((EnrichableException) t).addInfo(
                    errorContext, errorCode, errorText);
            }
        }

        public void raise(String errorContext, String errorCode,
                          String errorText){
            throw new EnrichableException(
                errorContext, errorCode, errorText);
        }
    };

    public static void main(String[] args){
        ExceptionTest test = new ExceptionTest();
        try{
            test.level1();
        } catch(Exception e){
            e.printStackTrace();
        }
    }

    public void level1(){
        try{
            level2();
        } catch (EnrichableException e){
            this.exceptionHandler.handle(
                "L1", "E1", "Error in level 1, calling level 2", e);
            throw e;
        }
    }

    public void level2(){
        try{
            level3();
        } catch (EnrichableException e){
            this.exceptionHandler.handle(
                "L2", "E2", "Error in level 2, calling level 3", e);
            throw e;
        }
    }

    public void level3(){
        try{
            level4();
        } catch(Exception e){
            this.exceptionHandler.handle(
                "L3", "E3", "Error at level 3", e);
        }
    }

    public void level4(){
        throw new IllegalArgumentException("incorrect argument passed");
    }

}

```